### Assessment of Compatibility and Conversion Viability

The provided Python code appears to be implementing a decorator called `math_eval` using the `swarms.utils` module. The code defines several test functions that utilize this decorator to compare the results of two functions, either with or without exceptions. 

After analyzing the Python code, I conclude that conversion to Rust is viable. However, some considerations are necessary to ensure compatibility and functionality:

*   The `math_eval` decorator seems to be responsible for handling exceptions and comparing function results. In Rust, this could be achieved using a closure or a trait object to wrap the functions and handle exceptions using the `Result` type.
*   The Python `caplog` object is used to capture log messages. In Rust, a similar functionality can be achieved using the `log` crate and a custom logger implementation.
*   The Python code uses the `assert` statement for testing. Rust provides a similar functionality through the `assert!` macro.

Here's a potential conversion of the provided Python code into Rust:

```rust
// This conversion is viable. The decorator pattern in Python can be replaced
// with a closure or trait object in Rust. The logging functionality can be
// achieved using the `log` crate. However, some Rust-specific considerations
// are necessary, such as error handling and ownership.

use std::panic;

// Define a trait for functions that take one argument
trait MathFunc {
    fn call(&self, x: i32) -> Result<i32, String>;
}

// Implement the MathFunc trait for closures
impl<F> MathFunc for F
where
    F: Fn(i32) -> Result<i32, String> + 'static,
{
    fn call(&self, x: i32) -> Result<i32, String> {
        self(x)
    }
}

// Define a struct to hold the results and log messages
struct TestResults {
    results: (Option<i32>, i32),
    log_message: String,
}

// Define a function that wraps two functions with MathFunc trait and calls them
fn test_func<F1, F2>(func1: F1, func2: F2, x: i32) -> TestResults
where
    F1: MathFunc + 'static,
    F2: MathFunc + 'static,
{
    // Initialize the log message
    let mut log_message = String::new();

    // Call the first function and handle any panic
    let result1 = panic::catch_unwind(|| func1.call(x))
        .map_err(|_| {
            // If a panic occurs, append the error message to the log
            log_message.push_str("Error in func1: Panic occurred\n");
            None
        })
        .unwrap_or(None);

    // Call the second function
    let result2 = func2.call(x).unwrap_or_else(|err| {
        // If an error occurs, append the error message to the log
        log_message.push_str(&format!("Error in func2: {}\n", err));
        panic::catch_unwind(|| 0).unwrap_or(0)
    });

    // Compare the results and append the log message if they don't match
    if let (Some(result1), result2) = (result1, result2) {
        if result1 != result2 {
            log_message.push_str("Outputs do not match\n");
        }
    }

    TestResults {
        results: (result1, result2),
        log_message,
    }
}

fn func1_no_exception(x: i32) -> Result<i32, String> {
    // This function does not raise any exception
    Ok(x + 2)
}

fn func2_no_exception(x: i32) -> Result<i32, String> {
    // This function does not raise any exception
    Ok(x + 2)
}

fn func1_with_exception(_x: i32) -> Result<i32, String> {
    // This function raises an exception
    Err("Error occurred".to_string())
}

fn func2_with_exception(_x: i32) -> Result<i32, String> {
    // This function raises an exception
    Err("Error occurred".to_string())
}

fn main() {
    // Test the test_func function with functions that do not raise exceptions
    let results = test_func(&func1_no_exception, &func2_no_exception, 5);
    assert!(results.results.0 == Some(7));
    assert!(results.results.1 == 7);
    assert!(!results.log_message.contains("Outputs do not match"));
    assert!(results.log_message.is_empty());

    // Test the test_func function with a function that raises an exception
    let results = test_func(&func1_with_exception, &func2_no_exception, 5);
    assert!(results.results.0.is_none());
    assert!(results.results.1 == 7);
    assert!(results.log_message.contains("Error in func1: Error occurred"));
}
```

This Rust code achieves similar functionality to the provided Python code. However, some differences exist due to the language's characteristics:

*   Error handling in Rust is more explicit and robust, utilizing the `Result` type to handle errors in a more controlled manner.
*   Rust's ownership system requires careful consideration when working with closures and trait objects.
*   Logging functionality in Rust can be achieved using the `log` crate, but it may require a custom implementation to match the Python `caplog` object's behavior.
*   The `assert!` macro in Rust provides a similar functionality to Python's `assert` statement, but it will panic if the condition is not met.

Overall, converting the provided Python code to Rust requires consideration of these differences and the use of Rust-specific features to achieve the desired functionality.