### Conversion Assessment
The provided Python file contains four test functions that utilize the `@try_except_wrapper` decorator. To convert this code to Rust, we need to consider the following:
*   The `try_except_wrapper` decorator is not a standard Python decorator, and its implementation is not provided. Therefore, we will need to create a Rust equivalent.
*   Rust does not support decorators in the same way Python does. However, we can use a trait or a macro to achieve similar functionality.
*   Error handling in Rust is more explicit and verbose compared to Python.

Overall, the conversion is viable, but it will require additional effort to replicate the decorator's behavior in Rust.

### Rust Implementation
```rust
// Viability: Viable
// Reasoning: The conversion requires replicating the try_except_wrapper decorator's behavior in Rust.
// This can be achieved using a trait, macro, or a custom wrapper function.

use std::fmt;

// Define a trait for the try_except_wrapper behavior
trait TryExceptWrapper {
    fn call(&self) -> Result<(), Box<dyn std::error::Error>>;
}

// Implement the trait for a closure
struct TryExceptWrapperClosure<F>
where
    F: Fn() -> Result<(), Box<dyn std::error::Error>>,
{
    closure: F,
}

impl<F> TryExceptWrapperClosure<F>
where
    F: Fn() -> Result<(), Box<dyn std::error::Error>>,
{
    fn new(closure: F) -> Self {
        Self { closure }
    }
}

impl<F> TryExceptWrapper for TryExceptWrapperClosure<F>
where
    F: Fn() -> Result<(), Box<dyn std::error::Error>>,
{
    fn call(&self) -> Result<(), Box<dyn std::error::Error>> {
        (self.closure)()
    }
}

// Define test functions
fn test_try_except_wrapper_with_no_exception() {
    let add = |x: i32, y: i32| {
        Ok(x + y)
    };

    let result = try_except_wrapper(add, 1, 2);
    assert_eq!(result.unwrap(), 3);
}

fn test_try_except_wrapper_with_exception() {
    let divide = |x: i32, y: i32| {
        if y == 0 {
            Err(Box::new(std::io::Error::new(
                std::io::ErrorKind::InvalidInput,
                "Division by zero",
            )))
        } else {
            Ok(x / y)
        }
    };

    let result = try_except_wrapper(divide, 1, 0);
    assert!(result.is_err());
}

fn test_try_except_wrapper_with_multiple_arguments() {
    let concatenate = |args: Vec<String>| {
        Ok(args.join(" "))
    };

    let result = try_except_wrapper_concatenate(concatenate, vec!["Hello".to_string(), "world".to_string()]);
    assert_eq!(result.unwrap(), "Hello world");
}

fn test_try_except_wrapper_with_keyword_arguments() {
    let greet = |name: String| {
        Ok(format!("Hello, {}", name))
    };

    let result = try_except_wrapper_greet(greet, "Alice".to_string());
    assert_eq!(result.unwrap(), "Hello, Alice");
}

// Define a try_except_wrapper function
fn try_except_wrapper<F>(closure: F, arg1: i32, arg2: i32) -> Result<i32, Box<dyn std::error::Error>>
where
    F: Fn(i32, i32) -> Result<i32, Box<dyn std::error::Error>>,
{
    let wrapper = TryExceptWrapperClosure::new(move || closure(arg1, arg2));
    wrapper.call().map_err(|e| e)
}

fn try_except_wrapper_concatenate<F>(closure: F, args: Vec<String>) -> Result<String, Box<dyn std::error::Error>>
where
    F: Fn(Vec<String>) -> Result<String, Box<dyn std::error::Error>>,
{
    let wrapper = TryExceptWrapperClosure::new(move || closure(args));
    wrapper.call().map_err(|e| e)
}

fn try_except_wrapper_greet<F>(closure: F, name: String) -> Result<String, Box<dyn std::error::Error>>
where
    F: Fn(String) -> Result<String, Box<dyn std::error::Error>>,
{
    let wrapper = TryExceptWrapperClosure::new(move || closure(name));
    wrapper.call().map_err(|e| e)
}

fn main() {
    test_try_except_wrapper_with_no_exception();
    test_try_except_wrapper_with_exception();
    test_try_except_wrapper_with_multiple_arguments();
    test_try_except_wrapper_with_keyword_arguments();
}
```

### Challenges and Limitations
*   Rust's error handling is more explicit and verbose than Python's, which requires additional code to handle errors.
*   The `try_except_wrapper` decorator is not a standard Python decorator, so its behavior needs to be replicated in Rust.
*   The Rust implementation uses a trait and a struct to achieve similar functionality to the Python decorator.
*   The `try_except_wrapper` function is defined to wrap the closure and handle errors, but it requires generic type parameters to accommodate different closure types.

### Example Use Cases
*   The provided test functions demonstrate how to use the `try_except_wrapper` function to wrap closures and handle errors in various scenarios.
*   The `try_except_wrapper` function can be used to wrap any closure that returns a `Result` type, making it a versatile tool for error handling in Rust.

Note that the Rust implementation is more verbose than the Python code due to the differences in language design and error handling mechanisms. However, the Rust code provides a clear and maintainable solution for achieving similar functionality to the Python decorator.